I'm sorry, but an uncaught exception occurred.

While running game code:
  File "game/act_one.rpy", line 57, in script
    ar "What kind of “chosen hero” gets caught in a simple trap like this?"
Exception: Sayer 'ar' is not defined.

-- Full Traceback ------------------------------------------------------------

Full traceback:
  File "game/act_one.rpy", line 57, in script
    ar "What kind of “chosen hero” gets caught in a simple trap like this?"
  File "D:\Renpy\renpy-8.2.0-sdk\renpy\ast.py", line 2557, in execute
    Say.execute(self)
  File "D:\Renpy\renpy-8.2.0-sdk\renpy\ast.py", line 575, in execute
    who = eval_who(self.who, self.who_fast)
  File "D:\Renpy\renpy-8.2.0-sdk\renpy\ast.py", line 464, in eval_who
    raise Exception("Sayer '%s' is not defined." % who)
Exception: Sayer 'ar' is not defined.

Windows-10-10.0.19045 AMD64
Ren'Py 8.2.0.24012702
Luvelian 1.0
Mon Mar 11 01:23:40 2024
